<?xml version="1.0"?>

<robot name="sphero6d" xmlns:xacro="http://www.ros.org/wiki/xacro">
	<xacro:property name="robot_params" value="${load_yaml('$(find sphero6d_description)/config/init_config.yaml')}" />
	<xacro:property name="sphere_properies" value="${robot_params['sphere']}" />
	<xacro:property name="radius" value="${sphere_properies['radius']}" />
	<xacro:property name="max_velocity" value="${sphere_properies['max_velocity']}" />
	<xacro:property name="joints_properties" value="${robot_params['joints']}" />
	<xacro:property name="x_lower_limit" value="${joints_properties['x_lower_limit']}" />
	<xacro:property name="x_upper_limit" value="${joints_properties['x_upper_limit']}" />
	<xacro:property name="y_lower_limit" value="${joints_properties['y_lower_limit']}" />
	<xacro:property name="y_upper_limit" value="${joints_properties['y_upper_limit']}" />
	<xacro:property name="z_lower_limit" value="${joints_properties['z_lower_limit']}" />
	<xacro:property name="z_upper_limit" value="${joints_properties['z_upper_limit']}" />

  <link name="base_link">
  </link>

  <link name="translation_x">
  </link>

  <link name="translation_y">
  </link>

  <link name="translation_z">
  </link>

  <link name="rotation_x">
  </link>

  <link name="rotation_y">
  </link>

  <link name="rotation_z">
    <visual>
      <geometry>
				<sphere radius="${radius}"/>
      </geometry>
    </visual>
  </link>

  <joint name="x" type="prismatic">
    <parent link="base_link"/>
    <child link="translation_x"/>
		<axis xyz="1 0 0" />
		<limit effort="30" velocity="${max_velocity}" lower="${x_lower_limit}" upper="${x_upper_limit}" />
  </joint>

  <joint name="y" type="prismatic">
    <parent link="translation_x"/>
    <child link="translation_y"/>
		<axis xyz="0 1 0" />
		<limit effort="30" velocity="${max_velocity}" lower="${y_lower_limit}" upper="${y_upper_limit}" />
  </joint>

  <joint name="z" type="prismatic">
    <parent link="translation_y"/>
    <child link="translation_z"/>
		<axis xyz="0 0 1" />
		<limit effort="30" velocity="${max_velocity}" lower="${z_lower_limit}" upper="${z_upper_limit}" />
  </joint>

  <joint name="ang_x" type="continuous">
    <parent link="translation_z"/>
    <child link="rotation_x"/>
		<axis xyz="1 0 0" />
  </joint>

  <joint name="ang_y" type="continuous">
    <parent link="rotation_x"/>
    <child link="rotation_y"/>
		<axis xyz="0 1 0" />
  </joint>

  <joint name="ang_z" type="continuous">
    <parent link="rotation_y"/>
    <child link="rotation_z"/>
		<axis xyz="0 0 1" />
  </joint>

</robot>
